C:\Users\LENOVO\AppData\Local\Programs\Python\Python311\python.exe "E:\SAP_Integ\Git Change\20250720\2\Emerging_BarCode_Integration\main.py" 
Traceback (most recent call last):
  File "C:\Users\LENOVO\AppData\Local\Programs\Python\Python311\Lib\site-packages\sqlalchemy\engine\base.py", line 1969, in _exec_single_context
    self.dialect.do_execute(
  File "C:\Users\LENOVO\AppData\Local\Programs\Python\Python311\Lib\site-packages\sqlalchemy\engine\default.py", line 922, in do_execute
    cursor.execute(statement, parameters)
  File "C:\Users\LENOVO\AppData\Local\Programs\Python\Python311\Lib\site-packages\pymysql\cursors.py", line 153, in execute
    result = self._query(query)
             ^^^^^^^^^^^^^^^^^^
  File "C:\Users\LENOVO\AppData\Local\Programs\Python\Python311\Lib\site-packages\pymysql\cursors.py", line 322, in _query
    conn.query(q)
  File "C:\Users\LENOVO\AppData\Local\Programs\Python\Python311\Lib\site-packages\pymysql\connections.py", line 563, in query
    self._affected_rows = self._read_query_result(unbuffered=unbuffered)
                          ^^^^^^^^^^^^^^^^^^^^^^^^^^^^^^^^^^^^^^^^^^^^^^
  File "C:\Users\LENOVO\AppData\Local\Programs\Python\Python311\Lib\site-packages\pymysql\connections.py", line 825, in _read_query_result
    result.read()
  File "C:\Users\LENOVO\AppData\Local\Programs\Python\Python311\Lib\site-packages\pymysql\connections.py", line 1199, in read
    first_packet = self.connection._read_packet()
                   ^^^^^^^^^^^^^^^^^^^^^^^^^^^^^^
  File "C:\Users\LENOVO\AppData\Local\Programs\Python\Python311\Lib\site-packages\pymysql\connections.py", line 775, in _read_packet
    packet.raise_for_error()
  File "C:\Users\LENOVO\AppData\Local\Programs\Python\Python311\Lib\site-packages\pymysql\protocol.py", line 219, in raise_for_error
    err.raise_mysql_exception(self._data)
  File "C:\Users\LENOVO\AppData\Local\Programs\Python\Python311\Lib\site-packages\pymysql\err.py", line 150, in raise_mysql_exception
    raise errorclass(errno, errval)
pymysql.err.OperationalError: (1054, "Unknown column 'branches.name' in 'field list'")

The above exception was the direct cause of the following exception:

Traceback (most recent call last):
  File "E:\SAP_Integ\Git Change\20250720\2\Emerging_BarCode_Integration\main.py", line 1, in <module>
    from app import app
  File "E:\SAP_Integ\Git Change\20250720\2\Emerging_BarCode_Integration\app.py", line 167, in <module>
    default_branch = models_extensions.Branch.query.filter_by(id='BR001').first()
                     ^^^^^^^^^^^^^^^^^^^^^^^^^^^^^^^^^^^^^^^^^^^^^^^^^^^^^^^^^^^^
  File "C:\Users\LENOVO\AppData\Local\Programs\Python\Python311\Lib\site-packages\sqlalchemy\orm\query.py", line 2748, in first
    return self.limit(1)._iter().first()  # type: ignore
           ^^^^^^^^^^^^^^^^^^^^^
  File "C:\Users\LENOVO\AppData\Local\Programs\Python\Python311\Lib\site-packages\sqlalchemy\orm\query.py", line 2847, in _iter
    result: Union[ScalarResult[_T], Result[_T]] = self.session.execute(
                                                  ^^^^^^^^^^^^^^^^^^^^^
  File "C:\Users\LENOVO\AppData\Local\Programs\Python\Python311\Lib\site-packages\sqlalchemy\orm\session.py", line 2308, in execute
    return self._execute_internal(
           ^^^^^^^^^^^^^^^^^^^^^^^
  File "C:\Users\LENOVO\AppData\Local\Programs\Python\Python311\Lib\site-packages\sqlalchemy\orm\session.py", line 2190, in _execute_internal
    result: Result[Any] = compile_state_cls.orm_execute_statement(
                          ^^^^^^^^^^^^^^^^^^^^^^^^^^^^^^^^^^^^^^^^
  File "C:\Users\LENOVO\AppData\Local\Programs\Python\Python311\Lib\site-packages\sqlalchemy\orm\context.py", line 293, in orm_execute_statement
    result = conn.execute(
             ^^^^^^^^^^^^^
  File "C:\Users\LENOVO\AppData\Local\Programs\Python\Python311\Lib\site-packages\sqlalchemy\engine\base.py", line 1416, in execute
    return meth(
           ^^^^^
  File "C:\Users\LENOVO\AppData\Local\Programs\Python\Python311\Lib\site-packages\sqlalchemy\sql\elements.py", line 516, in _execute_on_connection
    return connection._execute_clauseelement(
           ^^^^^^^^^^^^^^^^^^^^^^^^^^^^^^^^^^
  File "C:\Users\LENOVO\AppData\Local\Programs\Python\Python311\Lib\site-packages\sqlalchemy\engine\base.py", line 1639, in _execute_clauseelement
    ret = self._execute_context(
          ^^^^^^^^^^^^^^^^^^^^^^
  File "C:\Users\LENOVO\AppData\Local\Programs\Python\Python311\Lib\site-packages\sqlalchemy\engine\base.py", line 1848, in _execute_context
    return self._exec_single_context(
           ^^^^^^^^^^^^^^^^^^^^^^^^^^
  File "C:\Users\LENOVO\AppData\Local\Programs\Python\Python311\Lib\site-packages\sqlalchemy\engine\base.py", line 1988, in _exec_single_context
    self._handle_dbapi_exception(
  File "C:\Users\LENOVO\AppData\Local\Programs\Python\Python311\Lib\site-packages\sqlalchemy\engine\base.py", line 2343, in _handle_dbapi_exception
    raise sqlalchemy_exception.with_traceback(exc_info[2]) from e
  File "C:\Users\LENOVO\AppData\Local\Programs\Python\Python311\Lib\site-packages\sqlalchemy\engine\base.py", line 1969, in _exec_single_context
    self.dialect.do_execute(
  File "C:\Users\LENOVO\AppData\Local\Programs\Python\Python311\Lib\site-packages\sqlalchemy\engine\default.py", line 922, in do_execute
    cursor.execute(statement, parameters)
  File "C:\Users\LENOVO\AppData\Local\Programs\Python\Python311\Lib\site-packages\pymysql\cursors.py", line 153, in execute
    result = self._query(query)
             ^^^^^^^^^^^^^^^^^^
  File "C:\Users\LENOVO\AppData\Local\Programs\Python\Python311\Lib\site-packages\pymysql\cursors.py", line 322, in _query
    conn.query(q)
  File "C:\Users\LENOVO\AppData\Local\Programs\Python\Python311\Lib\site-packages\pymysql\connections.py", line 563, in query
    self._affected_rows = self._read_query_result(unbuffered=unbuffered)
                          ^^^^^^^^^^^^^^^^^^^^^^^^^^^^^^^^^^^^^^^^^^^^^^
  File "C:\Users\LENOVO\AppData\Local\Programs\Python\Python311\Lib\site-packages\pymysql\connections.py", line 825, in _read_query_result
    result.read()
  File "C:\Users\LENOVO\AppData\Local\Programs\Python\Python311\Lib\site-packages\pymysql\connections.py", line 1199, in read
    first_packet = self.connection._read_packet()
                   ^^^^^^^^^^^^^^^^^^^^^^^^^^^^^^
  File "C:\Users\LENOVO\AppData\Local\Programs\Python\Python311\Lib\site-packages\pymysql\connections.py", line 775, in _read_packet
    packet.raise_for_error()
  File "C:\Users\LENOVO\AppData\Local\Programs\Python\Python311\Lib\site-packages\pymysql\protocol.py", line 219, in raise_for_error
    err.raise_mysql_exception(self._data)
  File "C:\Users\LENOVO\AppData\Local\Programs\Python\Python311\Lib\site-packages\pymysql\err.py", line 150, in raise_mysql_exception
    raise errorclass(errno, errval)
sqlalchemy.exc.OperationalError: (pymysql.err.OperationalError) (1054, "Unknown column 'branches.name' in 'field list'")
[SQL: SELECT branches.id AS branches_id, branches.name AS branches_name, branches.address AS branches_address, branches.phone AS branches_phone, branches.email AS branches_email, branches.manager_name AS branches_manager_name, branches.is_active AS branches_is_active, branches.is_default AS branches_is_default, branches.created_at AS branches_created_at, branches.updated_at AS branches_updated_at 
FROM branches 
WHERE branches.id = %(id_1)s 
 LIMIT %(param_1)s]
[parameters: {'id_1': 'BR001', 'param_1': 1}]
(Background on this error at: https://sqlalche.me/e/20/e3q8)

Process finished with exit code 1
