ValueError
ValueError: unconverted data remains: T00:00:00Z

Traceback (most recent call last)
File "C:\Users\LENOVO\AppData\Local\Programs\Python\Python311\Lib\site-packages\flask\app.py", line 1498, in __call__
return self.wsgi_app(environ, start_response)
       ^^^^^^^^^^^^^^^^^^^^^^^^^^^^^^^^^^^^^^
File "C:\Users\LENOVO\AppData\Local\Programs\Python\Python311\Lib\site-packages\werkzeug\middleware\proxy_fix.py", line 183, in __call__
return self.app(environ, start_response)
       ^^^^^^^^^^^^^^^^^^^^^^^^^^^^^^^^^
File "C:\Users\LENOVO\AppData\Local\Programs\Python\Python311\Lib\site-packages\flask\app.py", line 1476, in wsgi_app
response = self.handle_exception(e)
           ^^^^^^^^^^^^^^^^^^^^^^^^
File "C:\Users\LENOVO\AppData\Local\Programs\Python\Python311\Lib\site-packages\flask\app.py", line 1473, in wsgi_app
response = self.full_dispatch_request()
           ^^^^^^^^^^^^^^^^^^^^^^^^^^^^
File "C:\Users\LENOVO\AppData\Local\Programs\Python\Python311\Lib\site-packages\flask\app.py", line 882, in full_dispatch_request
rv = self.handle_user_exception(e)
     ^^^^^^^^^^^^^^^^^^^^^^^^^^^^^
File "C:\Users\LENOVO\AppData\Local\Programs\Python\Python311\Lib\site-packages\flask\app.py", line 880, in full_dispatch_request
rv = self.dispatch_request()
     ^^^^^^^^^^^^^^^^^^^^^^^
File "C:\Users\LENOVO\AppData\Local\Programs\Python\Python311\Lib\site-packages\flask\app.py", line 865, in dispatch_request
return self.ensure_sync(self.view_functions[rule.endpoint])(**view_args)  # type: ignore[no-any-return]
       ^^^^^^^^^^^^^^^^^^^^^^^^^^^^^^^^^^^^^^^^^^^^^^^^^^^^^^^^^^^^^^^^^
File "C:\Users\LENOVO\AppData\Local\Programs\Python\Python311\Lib\site-packages\flask_login\utils.py", line 290, in decorated_view
return current_app.ensure_sync(func)(*args, **kwargs)
       ^^^^^^^^^^^^^^^^^^^^^^^^^^^^^^^^^^^^^^^^^^^^^^
File "E:\SAP_Integ\Git Change\3\Emerging_BarCode_Integration-main\Emerging_BarCode_Integration-main\routes.py", line 112, in create_grpo
    # Create GRPO document with PO details
    grpo_doc = GRPODocument(
        po_number=po_number,
        supplier_code=po_data.get('CardCode'),
        supplier_name=po_data.get('CardName'),
        po_date=datetime.strptime(po_data.get('DocDate', '2025-01-08'), '%Y-%m-%d') if po_data.get('DocDate') else datetime.utcnow(),
                ^^^^^^^^^^^^^^^^^^^^^^^^^^^^^^^^^^^^^^^^^^^^^^^^^^^^^^^^^^^^^^^^^^^
        po_total=po_data.get('DocTotal', 0),
        user_id=current_user.id,
        draft_or_post=request.form.get('draft_or_post', 'draft')
    )
    db.session.add(grpo_doc)
File "C:\Users\LENOVO\AppData\Local\Programs\Python\Python311\Lib\_strptime.py", line 567, in _strptime_datetime
tt, fraction, gmtoff_fraction = _strptime(data_string, format)
                                ^^^^^^^^^^^^^^^^^^^^^^^^^^^^^^
File "C:\Users\LENOVO\AppData\Local\Programs\Python\Python311\Lib\_strptime.py", line 352, in _strptime
raise ValueError("unconverted data remains: %s" %
^^^^^^^^^^^^^^^^^^^^^^^^^^^^^^^^^^^^^^^^^^^^
ValueError: unconverted data remains: T00:00:00Z
The debugger caught an exception in your WSGI application. You can now look at the traceback which led to the error.
To switch between the interactive traceback and the plaintext one, you can click on the "Traceback" headline. From the text traceback you can also create a paste of it.

Brought to you by DON'T PANIC, your friendly Werkzeug powered traceback interpreter.