2025-08-12 17:56:15,879 - INFO - MySQL connection closed
PS E:\SAP_Integ\Git Change\20250812\8\New_Update_Barcode> python main.py                            
ERROR:root:Error initializing default data: (pymysql.err.OperationalError) (1054, "Unknown column 'branches.name' in 'field list'")
[SQL: SELECT branches.id AS branches_id, branches.name AS branches_name, branches.description AS branches_description, branches.is_active AS branches_is_active, branches.created_at
 AS branches_created_at, branches.address AS branches_address, branches.phone AS branches_phone, branches.email AS branches_email, branches.manager_name AS branches_manager_name, branches.is_default AS branches_is_default, branches.updated_at AS branches_updated_at
FROM branches
WHERE branches.id = %(id_1)s
 LIMIT %(param_1)s]
[parameters: {'id_1': 'BR001', 'param_1': 1}]
(Background on this error at: https://sqlalche.me/e/20/e3q8)
 * Serving Flask app 'app'
 * Debug mode: on
INFO:werkzeug:WARNING: This is a development server. Do not use it in a production deployment. Use a production WSGI server instead.
 * Running on all addresses (0.0.0.0)
 * Running on http://127.0.0.1:5000
 * Running on http://192.168.0.153:5000
INFO:werkzeug:Press CTRL+C to quit
INFO:werkzeug: * Restarting with stat
ERROR:root:Error initializing default data: (pymysql.err.OperationalError) (1054, "Unknown column 'branches.name' in 'field list'")
[SQL: SELECT branches.id AS branches_id, branches.name AS branches_name, branches.description AS branches_description, branches.is_active AS branches_is_active, branches.created_at
 AS branches_created_at, branches.address AS branches_address, branches.phone AS branches_phone, branches.email AS branches_email, branches.manager_name AS branches_manager_name, branches.is_default AS branches_is_default, branches.updated_at AS branches_updated_at
FROM branches
WHERE branches.id = %(id_1)s
 LIMIT %(param_1)s]
[parameters: {'id_1': 'BR001', 'param_1': 1}]
(Background on this error at: https://sqlalche.me/e/20/e3q8)
WARNING:werkzeug: * Debugger is active!
INFO:werkzeug: * Debugger PIN: 888-243-362
INFO:werkzeug:192.168.0.153 - - [12/Aug/2025 17:57:03] "GET / HTTP/1.1" 302 -
INFO:werkzeug:192.168.0.153 - - [12/Aug/2025 17:57:03] "GET /login HTTP/1.1" 500 -
Traceback (most recent call last):
  File "C:\Users\LENOVO\AppData\Local\Programs\Python\Python311\Lib\site-packages\sqlalchemy\engine\base.py", line 1969, in _exec_single_context
    self.dialect.do_execute(
  File "C:\Users\LENOVO\AppData\Local\Programs\Python\Python311\Lib\site-packages\sqlalchemy\engine\default.py", line 922, in do_execute
    cursor.execute(statement, parameters)
  File "C:\Users\LENOVO\AppData\Local\Programs\Python\Python311\Lib\site-packages\pymysql\cursors.py", line 153, in execute
    result = self._query(query)
             ^^^^^^^^^^^^^^^^^^
  File "C:\Users\LENOVO\AppData\Local\Programs\Python\Python311\Lib\site-packages\pymysql\cursors.py", line 322, in _query
    conn.query(q)
  File "C:\Users\LENOVO\AppData\Local\Programs\Python\Python311\Lib\site-packages\pymysql\connections.py", line 563, in query
    self._affected_rows = self._read_query_result(unbuffered=unbuffered)
                          ^^^^^^^^^^^^^^^^^^^^^^^^^^^^^^^^^^^^^^^^^^^^^^
  File "C:\Users\LENOVO\AppData\Local\Programs\Python\Python311\Lib\site-packages\pymysql\connections.py", line 825, in _read_query_result
    result.read()
  File "C:\Users\LENOVO\AppData\Local\Programs\Python\Python311\Lib\site-packages\pymysql\connections.py", line 1199, in read
    first_packet = self.connection._read_packet()
                   ^^^^^^^^^^^^^^^^^^^^^^^^^^^^^^
  File "C:\Users\LENOVO\AppData\Local\Programs\Python\Python311\Lib\site-packages\pymysql\connections.py", line 775, in _read_packet
    packet.raise_for_error()
  File "C:\Users\LENOVO\AppData\Local\Programs\Python\Python311\Lib\site-packages\pymysql\protocol.py", line 219, in raise_for_error
    err.raise_mysql_exception(self._data)
  File "C:\Users\LENOVO\AppData\Local\Programs\Python\Python311\Lib\site-packages\pymysql\err.py", line 150, in raise_mysql_exception
    raise errorclass(errno, errval)
pymysql.err.OperationalError: (1054, "Unknown column 'name' in 'field list'")

The above exception was the direct cause of the following exception:

Traceback (most recent call last):
  File "C:\Users\LENOVO\AppData\Local\Programs\Python\Python311\Lib\site-packages\flask\app.py", line 1478, in __call__
    return self.wsgi_app(environ, start_response)
           ^^^^^^^^^^^^^^^^^^^^^^^^^^^^^^^^^^^^^^
  File "C:\Users\LENOVO\AppData\Local\Programs\Python\Python311\Lib\site-packages\werkzeug\middleware\proxy_fix.py", line 182, in __call__
    return self.app(environ, start_response)
           ^^^^^^^^^^^^^^^^^^^^^^^^^^^^^^^^^
  File "C:\Users\LENOVO\AppData\Local\Programs\Python\Python311\Lib\site-packages\flask\app.py", line 1458, in wsgi_app
    response = self.handle_exception(e)
               ^^^^^^^^^^^^^^^^^^^^^^^^
  File "C:\Users\LENOVO\AppData\Local\Programs\Python\Python311\Lib\site-packages\flask\app.py", line 1455, in wsgi_app
    response = self.full_dispatch_request()
               ^^^^^^^^^^^^^^^^^^^^^^^^^^^^
  File "C:\Users\LENOVO\AppData\Local\Programs\Python\Python311\Lib\site-packages\flask\app.py", line 869, in full_dispatch_request
    rv = self.handle_user_exception(e)
         ^^^^^^^^^^^^^^^^^^^^^^^^^^^^^
  File "C:\Users\LENOVO\AppData\Local\Programs\Python\Python311\Lib\site-packages\flask\app.py", line 867, in full_dispatch_request
    rv = self.dispatch_request()
         ^^^^^^^^^^^^^^^^^^^^^^^
  File "C:\Users\LENOVO\AppData\Local\Programs\Python\Python311\Lib\site-packages\flask\app.py", line 852, in dispatch_request
    return self.ensure_sync(self.view_functions[rule.endpoint])(**view_args)
           ^^^^^^^^^^^^^^^^^^^^^^^^^^^^^^^^^^^^^^^^^^^^^^^^^^^^^^^^^^^^^^^^^
  File "E:\SAP_Integ\Git Change\20250812\8\New_Update_Barcode\routes.py", line 363, in login
    branches = db.session.execute(db.text("SELECT id, name FROM branches WHERE is_active = TRUE ORDER BY name")).fetchall()
               ^^^^^^^^^^^^^^^^^^^^^^^^^^^^^^^^^^^^^^^^^^^^^^^^^^^^^^^^^^^^^^^^^^^^^^^^^^^^^^^^^^^^^^^^^^^^^^^^^^^^^^^^^^^^
  File "C:\Users\LENOVO\AppData\Local\Programs\Python\Python311\Lib\site-packages\sqlalchemy\orm\scoping.py", line 782, in execute
    return self._proxied.execute(
           ^^^^^^^^^^^^^^^^^^^^^^
  File "C:\Users\LENOVO\AppData\Local\Programs\Python\Python311\Lib\site-packages\sqlalchemy\orm\session.py", line 2308, in execute
    return self._execute_internal(
           ^^^^^^^^^^^^^^^^^^^^^^^
  File "C:\Users\LENOVO\AppData\Local\Programs\Python\Python311\Lib\site-packages\sqlalchemy\orm\session.py", line 2199, in _execute_internal
    result = conn.execute(
             ^^^^^^^^^^^^^
  File "C:\Users\LENOVO\AppData\Local\Programs\Python\Python311\Lib\site-packages\sqlalchemy\engine\base.py", line 1416, in execute
    return meth(
           ^^^^^
  File "C:\Users\LENOVO\AppData\Local\Programs\Python\Python311\Lib\site-packages\sqlalchemy\sql\elements.py", line 516, in _execute_on_connection
    return connection._execute_clauseelement(
           ^^^^^^^^^^^^^^^^^^^^^^^^^^^^^^^^^^
  File "C:\Users\LENOVO\AppData\Local\Programs\Python\Python311\Lib\site-packages\sqlalchemy\engine\base.py", line 1639, in _execute_clauseelement
    ret = self._execute_context(
          ^^^^^^^^^^^^^^^^^^^^^^
  File "C:\Users\LENOVO\AppData\Local\Programs\Python\Python311\Lib\site-packages\sqlalchemy\engine\base.py", line 1848, in _execute_context
    return self._exec_single_context(
           ^^^^^^^^^^^^^^^^^^^^^^^^^^
  File "C:\Users\LENOVO\AppData\Local\Programs\Python\Python311\Lib\site-packages\sqlalchemy\engine\base.py", line 1988, in _exec_single_context
    self._handle_dbapi_exception(
  File "C:\Users\LENOVO\AppData\Local\Programs\Python\Python311\Lib\site-packages\sqlalchemy\engine\base.py", line 2343, in _handle_dbapi_exception
    raise sqlalchemy_exception.with_traceback(exc_info[2]) from e
  File "C:\Users\LENOVO\AppData\Local\Programs\Python\Python311\Lib\site-packages\sqlalchemy\engine\base.py", line 1969, in _exec_single_context
    self.dialect.do_execute(
  File "C:\Users\LENOVO\AppData\Local\Programs\Python\Python311\Lib\site-packages\sqlalchemy\engine\default.py", line 922, in do_execute
    cursor.execute(statement, parameters)
  File "C:\Users\LENOVO\AppData\Local\Programs\Python\Python311\Lib\site-packages\pymysql\cursors.py", line 153, in execute
    result = self._query(query)
             ^^^^^^^^^^^^^^^^^^
  File "C:\Users\LENOVO\AppData\Local\Programs\Python\Python311\Lib\site-packages\pymysql\cursors.py", line 322, in _query
    conn.query(q)
  File "C:\Users\LENOVO\AppData\Local\Programs\Python\Python311\Lib\site-packages\pymysql\connections.py", line 563, in query
    self._affected_rows = self._read_query_result(unbuffered=unbuffered)
                          ^^^^^^^^^^^^^^^^^^^^^^^^^^^^^^^^^^^^^^^^^^^^^^
  File "C:\Users\LENOVO\AppData\Local\Programs\Python\Python311\Lib\site-packages\pymysql\connections.py", line 825, in _read_query_result
    result.read()
  File "C:\Users\LENOVO\AppData\Local\Programs\Python\Python311\Lib\site-packages\pymysql\connections.py", line 1199, in read
    first_packet = self.connection._read_packet()
                   ^^^^^^^^^^^^^^^^^^^^^^^^^^^^^^
  File "C:\Users\LENOVO\AppData\Local\Programs\Python\Python311\Lib\site-packages\pymysql\connections.py", line 775, in _read_packet
    packet.raise_for_error()
  File "C:\Users\LENOVO\AppData\Local\Programs\Python\Python311\Lib\site-packages\pymysql\protocol.py", line 219, in raise_for_error
    err.raise_mysql_exception(self._data)
  File "C:\Users\LENOVO\AppData\Local\Programs\Python\Python311\Lib\site-packages\pymysql\err.py", line 150, in raise_mysql_exception
    raise errorclass(errno, errval)
sqlalchemy.exc.OperationalError: (pymysql.err.OperationalError) (1054, "Unknown column 'name' in 'field list'")
[SQL: SELECT id, name FROM branches WHERE is_active = TRUE ORDER BY name]
(Background on this error at: https://sqlalche.me/e/20/e3q8)
INFO:werkzeug:192.168.0.153 - - [12/Aug/2025 17:57:04] "GET /login?__debugger__=yes&cmd=resource&f=style.css HTTP/1.1" 200 -
INFO:werkzeug:192.168.0.153 - - [12/Aug/2025 17:57:04] "GET /login?__debugger__=yes&cmd=resource&f=debugger.js HTTP/1.1" 200 -
INFO:werkzeug:192.168.0.153 - - [12/Aug/2025 17:57:04] "GET /login?__debugger__=yes&cmd=resource&f=console.png HTTP/1.1" 200 -
INFO:werkzeug:192.168.0.153 - - [12/Aug/2025 17:57:04] "GET /login?__debugger__=yes&cmd=resource&f=console.png HTTP/1.1" 304 -

