OperationalError
sqlalchemy.exc.OperationalError: (sqlite3.OperationalError) no such column: grpo_documents.supplier_code
[SQL: SELECT count(*) AS count_1 
FROM (SELECT grpo_documents.id AS grpo_documents_id, grpo_documents.po_number AS grpo_documents_po_number, grpo_documents.sap_document_number AS grpo_documents_sap_document_number, grpo_documents.supplier_code AS grpo_documents_supplier_code, grpo_documents.supplier_name AS grpo_documents_supplier_name, grpo_documents.po_date AS grpo_documents_po_date, grpo_documents.po_total AS grpo_documents_po_total, grpo_documents.status AS grpo_documents_status, grpo_documents.user_id AS grpo_documents_user_id, grpo_documents.qc_user_id AS grpo_documents_qc_user_id, grpo_documents.qc_notes AS grpo_documents_qc_notes, grpo_documents.draft_or_post AS grpo_documents_draft_or_post, grpo_documents.created_at AS grpo_documents_created_at, grpo_documents.updated_at AS grpo_documents_updated_at 
FROM grpo_documents 
WHERE grpo_documents.user_id = ?) AS anon_1]
[parameters: (1,)]
(Background on this error at: https://sqlalche.me/e/20/e3q8)

Traceback (most recent call last)
File "C:\Users\LENOVO\AppData\Local\Programs\Python\Python311\Lib\site-packages\sqlalchemy\engine\base.py", line 1963, in _exec_single_context
self.dialect.do_execute(
^
File "C:\Users\LENOVO\AppData\Local\Programs\Python\Python311\Lib\site-packages\sqlalchemy\engine\default.py", line 943, in do_execute
cursor.execute(statement, parameters)
^^^^^^^^^^^^^^^^^^^^^^^^^^^^^^^^^^^^^
The above exception was the direct cause of the following exception:
File "C:\Users\LENOVO\AppData\Local\Programs\Python\Python311\Lib\site-packages\flask\app.py", line 1498, in __call__
return self.wsgi_app(environ, start_response)
       ^^^^^^^^^^^^^^^^^^^^^^^^^^^^^^^^^^^^^^
File "C:\Users\LENOVO\AppData\Local\Programs\Python\Python311\Lib\site-packages\werkzeug\middleware\proxy_fix.py", line 183, in __call__
return self.app(environ, start_response)
       ^^^^^^^^^^^^^^^^^^^^^^^^^^^^^^^^^
File "C:\Users\LENOVO\AppData\Local\Programs\Python\Python311\Lib\site-packages\flask\app.py", line 1476, in wsgi_app
response = self.handle_exception(e)
           ^^^^^^^^^^^^^^^^^^^^^^^^
File "C:\Users\LENOVO\AppData\Local\Programs\Python\Python311\Lib\site-packages\flask\app.py", line 1473, in wsgi_app
response = self.full_dispatch_request()
           ^^^^^^^^^^^^^^^^^^^^^^^^^^^^
File "C:\Users\LENOVO\AppData\Local\Programs\Python\Python311\Lib\site-packages\flask\app.py", line 882, in full_dispatch_request
rv = self.handle_user_exception(e)
     ^^^^^^^^^^^^^^^^^^^^^^^^^^^^^
File "C:\Users\LENOVO\AppData\Local\Programs\Python\Python311\Lib\site-packages\flask\app.py", line 880, in full_dispatch_request
rv = self.dispatch_request()
     ^^^^^^^^^^^^^^^^^^^^^^^
File "C:\Users\LENOVO\AppData\Local\Programs\Python\Python311\Lib\site-packages\flask\app.py", line 865, in dispatch_request
return self.ensure_sync(self.view_functions[rule.endpoint])(**view_args)  # type: ignore[no-any-return]
       ^^^^^^^^^^^^^^^^^^^^^^^^^^^^^^^^^^^^^^^^^^^^^^^^^^^^^^^^^^^^^^^^^
File "C:\Users\LENOVO\AppData\Local\Programs\Python\Python311\Lib\site-packages\flask_login\utils.py", line 290, in decorated_view
return current_app.ensure_sync(func)(*args, **kwargs)
       ^^^^^^^^^^^^^^^^^^^^^^^^^^^^^^^^^^^^^^^^^^^^^^
File "E:\SAP_Integ\CrossPlatformInventory (2)\git\2\Emerging_BarCode_Integration-main\Emerging_BarCode_Integration-main\routes.py", line 58, in dashboard
grpo_count = GRPODocument.query.filter_by(user_id=current_user.id).count()
             ^^^^^^^^^^^^^^^^^^^^^^^^^^^^^^^^^^^^^^^^^^^^^^^^^^^^^^^^^^^^^
File "C:\Users\LENOVO\AppData\Local\Programs\Python\Python311\Lib\site-packages\sqlalchemy\orm\query.py", line 3146, in count
self._legacy_from_self(col).enable_eagerloads(False).scalar()
^^^^^^^^^^^^^^^^^^^^^^^^^^^^^^^^^^^^^^^^^^^^^^^^^^^^^^^^^^^^^
File "C:\Users\LENOVO\AppData\Local\Programs\Python\Python311\Lib\site-packages\sqlalchemy\orm\query.py", line 2835, in scalar
ret = self.one()
      ^^^^^^^^^^
File "C:\Users\LENOVO\AppData\Local\Programs\Python\Python311\Lib\site-packages\sqlalchemy\orm\query.py", line 2808, in one
return self._iter().one()  # type: ignore
       ^^^^^^^^^^^^
File "C:\Users\LENOVO\AppData\Local\Programs\Python\Python311\Lib\site-packages\sqlalchemy\orm\query.py", line 2857, in _iter
result: Union[ScalarResult[_T], Result[_T]] = self.session.execute(
                                              
File "C:\Users\LENOVO\AppData\Local\Programs\Python\Python311\Lib\site-packages\sqlalchemy\orm\session.py", line 2365, in execute
return self._execute_internal(
       
File "C:\Users\LENOVO\AppData\Local\Programs\Python\Python311\Lib\site-packages\sqlalchemy\orm\session.py", line 2251, in _execute_internal
result: Result[Any] = compile_state_cls.orm_execute_statement(
                      
File "C:\Users\LENOVO\AppData\Local\Programs\Python\Python311\Lib\site-packages\sqlalchemy\orm\context.py", line 306, in orm_execute_statement
result = conn.execute(
         
File "C:\Users\LENOVO\AppData\Local\Programs\Python\Python311\Lib\site-packages\sqlalchemy\engine\base.py", line 1415, in execute
return meth(
       
File "C:\Users\LENOVO\AppData\Local\Programs\Python\Python311\Lib\site-packages\sqlalchemy\sql\elements.py", line 523, in _execute_on_connection
return connection._execute_clauseelement(
       
File "C:\Users\LENOVO\AppData\Local\Programs\Python\Python311\Lib\site-packages\sqlalchemy\engine\base.py", line 1637, in _execute_clauseelement
ret = self._execute_context(
      
File "C:\Users\LENOVO\AppData\Local\Programs\Python\Python311\Lib\site-packages\sqlalchemy\engine\base.py", line 1842, in _execute_context
return self._exec_single_context(
       
File "C:\Users\LENOVO\AppData\Local\Programs\Python\Python311\Lib\site-packages\sqlalchemy\engine\base.py", line 1982, in _exec_single_context
self._handle_dbapi_exception(
^
File "C:\Users\LENOVO\AppData\Local\Programs\Python\Python311\Lib\site-packages\sqlalchemy\engine\base.py", line 2351, in _handle_dbapi_exception
raise sqlalchemy_exception.with_traceback(exc_info[2]) from e
^^^^^^^^^^^^^^^^^^^^^^^^^^^^^^^^^^^^^^^^^^^^^^^^^^^^^^^^^^^^^
File "C:\Users\LENOVO\AppData\Local\Programs\Python\Python311\Lib\site-packages\sqlalchemy\engine\base.py", line 1963, in _exec_single_context
self.dialect.do_execute(
^
File "C:\Users\LENOVO\AppData\Local\Programs\Python\Python311\Lib\site-packages\sqlalchemy\engine\default.py", line 943, in do_execute
cursor.execute(statement, parameters)
^^^^^^^^^^^^^^^^^^^^^^^^^^^^^^^^^^^^^
sqlalchemy.exc.OperationalError: (sqlite3.OperationalError) no such column: grpo_documents.supplier_code
[SQL: SELECT count(*) AS count_1
FROM (SELECT grpo_documents.id AS grpo_documents_id, grpo_documents.po_number AS grpo_documents_po_number, grpo_documents.sap_document_number AS grpo_documents_sap_document_number, grpo_documents.supplier_code AS grpo_documents_supplier_code, grpo_documents.supplier_name AS grpo_documents_supplier_name, grpo_documents.po_date AS grpo_documents_po_date, grpo_documents.po_total AS grpo_documents_po_total, grpo_documents.status AS grpo_documents_status, grpo_documents.user_id AS grpo_documents_user_id, grpo_documents.qc_user_id AS grpo_documents_qc_user_id, grpo_documents.qc_notes AS grpo_documents_qc_notes, grpo_documents.draft_or_post AS grpo_documents_draft_or_post, grpo_documents.created_at AS grpo_documents_created_at, grpo_documents.updated_at AS grpo_documents_updated_at
FROM grpo_documents
WHERE grpo_documents.user_id = ?) AS anon_1]
[parameters: (1,)]
(Background on this error at: https://sqlalche.me/e/20/e3q8)
The debugger caught an exception in your WSGI application. You can now look at the traceback which led to the error.
To switch between the interactive traceback and the plaintext one, you can click on the "Traceback" headline. From the text traceback you can also create a paste of it.

Brought to you by DON'T PANIC, your friendly Werkzeug powered traceback interpreter.